[2024-03-11T16:58:29.080+0000] {taskinstance.py:1979} INFO - Dependencies all met for dep_context=non-requeueable deps ti=<TaskInstance: Lead_scoring_training_pipeline.training_model manual__2024-03-11T16:58:16.987114+00:00 [queued]>
[2024-03-11T16:58:29.085+0000] {taskinstance.py:1979} INFO - Dependencies all met for dep_context=requeueable deps ti=<TaskInstance: Lead_scoring_training_pipeline.training_model manual__2024-03-11T16:58:16.987114+00:00 [queued]>
[2024-03-11T16:58:29.085+0000] {taskinstance.py:2193} INFO - Starting attempt 1 of 2
[2024-03-11T16:58:29.108+0000] {taskinstance.py:2217} INFO - Executing <Task(PythonOperator): training_model> on 2024-03-11 16:58:16.987114+00:00
[2024-03-11T16:58:29.116+0000] {standard_task_runner.py:60} INFO - Started process 1822 to run task
[2024-03-11T16:58:29.118+0000] {standard_task_runner.py:87} INFO - Running: ['airflow', 'tasks', 'run', 'Lead_scoring_training_pipeline', 'training_model', 'manual__2024-03-11T16:58:16.987114+00:00', '--job-id', '91', '--raw', '--subdir', 'DAGS_FOLDER/Lead_scoring_training_pipeline/lead_scoring_training_pipeline.py', '--cfg-path', '/tmp/tmp8gnl2wcz']
[2024-03-11T16:58:29.119+0000] {standard_task_runner.py:88} INFO - Job 91: Subtask training_model
[2024-03-11T16:58:29.157+0000] {task_command.py:423} INFO - Running <TaskInstance: Lead_scoring_training_pipeline.training_model manual__2024-03-11T16:58:16.987114+00:00 [running]> on host 026c09de2b63
[2024-03-11T16:58:29.225+0000] {taskinstance.py:2513} INFO - Exporting env vars: AIRFLOW_CTX_DAG_OWNER='airflow' AIRFLOW_CTX_DAG_ID='Lead_scoring_training_pipeline' AIRFLOW_CTX_TASK_ID='training_model' AIRFLOW_CTX_EXECUTION_DATE='2024-03-11T16:58:16.987114+00:00' AIRFLOW_CTX_TRY_NUMBER='1' AIRFLOW_CTX_DAG_RUN_ID='manual__2024-03-11T16:58:16.987114+00:00'
[2024-03-11T16:58:29.226+0000] {logging_mixin.py:188} INFO - /home/airflow/dags/Lead_scoring_data_pipeline
[2024-03-11T16:58:29.227+0000] {logging_mixin.py:188} INFO - ['data_validation_checks.py', 'constants.py', 'schema.py', 'lead_scoring_data_pipeline.py', 'utils.py', 'data', '.ipynb_checkpoints', 'mapping', '__pycache__', 'lead_scoring_data_cleaning.db']
[2024-03-11T16:58:29.227+0000] {logging_mixin.py:188} INFO - /home/mlfow/
[2024-03-11T16:58:29.227+0000] {logging_mixin.py:188} INFO - Lead_scoring_mlflow_production.db
[2024-03-11T16:58:29.227+0000] {logging_mixin.py:188} INFO - unable to open database file
[2024-03-11T16:58:29.230+0000] {logging_mixin.py:188} INFO - Loading 'features' table
[2024-03-11T16:58:33.198+0000] {logging_mixin.py:188} INFO - Loading 'target' table
[2024-03-11T16:58:33.450+0000] {utils.py:201} INFO - Creating mlflow experiment
[2024-03-11T16:58:33.864+0000] {connectionpool.py:810} WARNING - Retrying (JitteredRetry(total=4, connect=4, read=5, redirect=5, status=5)) after connection broken by 'NewConnectionError('<urllib3.connection.HTTPConnection object at 0x7f996a477580>: Failed to establish a new connection: [Errno -2] Name or service not known')': /api/2.0/mlflow/experiments/create
[2024-03-11T16:58:37.927+0000] {connectionpool.py:810} WARNING - Retrying (JitteredRetry(total=3, connect=3, read=5, redirect=5, status=5)) after connection broken by 'NewConnectionError('<urllib3.connection.HTTPConnection object at 0x7f996a4776a0>: Failed to establish a new connection: [Errno -2] Name or service not known')': /api/2.0/mlflow/experiments/create
[2024-03-11T16:58:45.997+0000] {connectionpool.py:810} WARNING - Retrying (JitteredRetry(total=2, connect=2, read=5, redirect=5, status=5)) after connection broken by 'NewConnectionError('<urllib3.connection.HTTPConnection object at 0x7f996a477910>: Failed to establish a new connection: [Errno -2] Name or service not known')': /api/2.0/mlflow/experiments/create
[2024-03-11T16:59:02.069+0000] {connectionpool.py:810} WARNING - Retrying (JitteredRetry(total=1, connect=1, read=5, redirect=5, status=5)) after connection broken by 'NewConnectionError('<urllib3.connection.HTTPConnection object at 0x7f996a477b20>: Failed to establish a new connection: [Errno -2] Name or service not known')': /api/2.0/mlflow/experiments/create
[2024-03-11T16:59:34.143+0000] {connectionpool.py:810} WARNING - Retrying (JitteredRetry(total=0, connect=0, read=5, redirect=5, status=5)) after connection broken by 'NewConnectionError('<urllib3.connection.HTTPConnection object at 0x7f996a477cd0>: Failed to establish a new connection: [Errno -2] Name or service not known')': /api/2.0/mlflow/experiments/create
[2024-03-11T16:59:34.269+0000] {connectionpool.py:810} WARNING - Retrying (JitteredRetry(total=4, connect=4, read=5, redirect=5, status=5)) after connection broken by 'NewConnectionError('<urllib3.connection.HTTPConnection object at 0x7f996a477610>: Failed to establish a new connection: [Errno -2] Name or service not known')': /api/2.0/mlflow/experiments/get-by-name?experiment_name=Lead_scoring_mlflow_production
[2024-03-11T16:59:38.328+0000] {connectionpool.py:810} WARNING - Retrying (JitteredRetry(total=3, connect=3, read=5, redirect=5, status=5)) after connection broken by 'NewConnectionError('<urllib3.connection.HTTPConnection object at 0x7f996a477c40>: Failed to establish a new connection: [Errno -2] Name or service not known')': /api/2.0/mlflow/experiments/get-by-name?experiment_name=Lead_scoring_mlflow_production
[2024-03-11T16:59:40.019+0000] {local_task_job_runner.py:302} WARNING - State of this instance has been externally set to failed. Terminating instance.
[2024-03-11T16:59:40.020+0000] {process_utils.py:131} INFO - Sending Signals.SIGTERM to group 1822. PIDs of all processes in the group: [1822]
[2024-03-11T16:59:40.021+0000] {process_utils.py:86} INFO - Sending the signal Signals.SIGTERM to group 1822
[2024-03-11T16:59:40.021+0000] {taskinstance.py:2483} ERROR - Received SIGTERM. Terminating subprocesses.
[2024-03-11T16:59:40.022+0000] {taskinstance.py:2731} ERROR - Task failed with exception
Traceback (most recent call last):
  File "/usr/local/lib/python3.8/dist-packages/urllib3/connection.py", line 174, in _new_conn
    conn = connection.create_connection(
  File "/usr/local/lib/python3.8/dist-packages/urllib3/util/connection.py", line 72, in create_connection
    for res in socket.getaddrinfo(host, port, family, socket.SOCK_STREAM):
  File "/usr/lib/python3.8/socket.py", line 918, in getaddrinfo
    for res in _socket.getaddrinfo(host, port, family, type, proto, flags):
socket.gaierror: [Errno -2] Name or service not known

During handling of the above exception, another exception occurred:

Traceback (most recent call last):
  File "/usr/local/lib/python3.8/dist-packages/urllib3/connectionpool.py", line 703, in urlopen
    httplib_response = self._make_request(
  File "/usr/local/lib/python3.8/dist-packages/urllib3/connectionpool.py", line 398, in _make_request
    conn.request(method, url, **httplib_request_kw)
  File "/usr/local/lib/python3.8/dist-packages/urllib3/connection.py", line 239, in request
    super(HTTPConnection, self).request(method, url, body=body, headers=headers)
  File "/usr/lib/python3.8/http/client.py", line 1256, in request
    self._send_request(method, url, body, headers, encode_chunked)
  File "/usr/lib/python3.8/http/client.py", line 1302, in _send_request
    self.endheaders(body, encode_chunked=encode_chunked)
  File "/usr/lib/python3.8/http/client.py", line 1251, in endheaders
    self._send_output(message_body, encode_chunked=encode_chunked)
  File "/usr/lib/python3.8/http/client.py", line 1011, in _send_output
    self.send(msg)
  File "/usr/lib/python3.8/http/client.py", line 951, in send
    self.connect()
  File "/usr/local/lib/python3.8/dist-packages/urllib3/connection.py", line 205, in connect
    conn = self._new_conn()
  File "/usr/local/lib/python3.8/dist-packages/urllib3/connection.py", line 186, in _new_conn
    raise NewConnectionError(
urllib3.exceptions.NewConnectionError: <urllib3.connection.HTTPConnection object at 0x7f996a477dc0>: Failed to establish a new connection: [Errno -2] Name or service not known

During handling of the above exception, another exception occurred:

Traceback (most recent call last):
  File "/usr/local/lib/python3.8/dist-packages/mlflow/utils/rest_utils.py", line 108, in http_request
    return _get_http_response_with_retries(
  File "/usr/local/lib/python3.8/dist-packages/mlflow/utils/request_utils.py", line 212, in _get_http_response_with_retries
    return session.request(method, url, allow_redirects=allow_redirects, **kwargs)
  File "/usr/local/lib/python3.8/dist-packages/requests/sessions.py", line 529, in request
    resp = self.send(prep, **send_kwargs)
  File "/usr/local/lib/python3.8/dist-packages/requests/sessions.py", line 645, in send
    r = adapter.send(request, **kwargs)
  File "/usr/local/lib/python3.8/dist-packages/requests/adapters.py", line 440, in send
    resp = conn.urlopen(
  File "/usr/local/lib/python3.8/dist-packages/urllib3/connectionpool.py", line 813, in urlopen
    return self.urlopen(
  File "/usr/local/lib/python3.8/dist-packages/urllib3/connectionpool.py", line 813, in urlopen
    return self.urlopen(
  File "/usr/local/lib/python3.8/dist-packages/urllib3/connectionpool.py", line 788, in urlopen
    retries.sleep()
  File "/usr/local/lib/python3.8/dist-packages/urllib3/util/retry.py", line 432, in sleep
    self._sleep_backoff()
  File "/usr/local/lib/python3.8/dist-packages/urllib3/util/retry.py", line 416, in _sleep_backoff
    time.sleep(backoff)
  File "/usr/local/lib/python3.8/dist-packages/airflow/models/taskinstance.py", line 2485, in signal_handler
    raise AirflowException("Task received SIGTERM signal")
airflow.exceptions.AirflowException: Task received SIGTERM signal

During handling of the above exception, another exception occurred:

Traceback (most recent call last):
  File "/usr/local/lib/python3.8/dist-packages/airflow/models/taskinstance.py", line 444, in _execute_task
    result = _execute_callable(context=context, **execute_callable_kwargs)
  File "/usr/local/lib/python3.8/dist-packages/airflow/models/taskinstance.py", line 414, in _execute_callable
    return execute_callable(context=context, **execute_callable_kwargs)
  File "/usr/local/lib/python3.8/dist-packages/airflow/operators/python.py", line 200, in execute
    return_value = self.execute_callable()
  File "/usr/local/lib/python3.8/dist-packages/airflow/operators/python.py", line 217, in execute_callable
    return self.python_callable(*self.op_args, **self.op_kwargs)
  File "/home/airflow/dags/Lead_scoring_training_pipeline/utils.py", line 204, in get_trained_model
    mlflow.set_experiment(EXPERIMENT)
  File "/usr/local/lib/python3.8/dist-packages/mlflow/tracking/fluent.py", line 142, in set_experiment
    experiment = client.get_experiment_by_name(experiment_name)
  File "/usr/local/lib/python3.8/dist-packages/mlflow/tracking/client.py", line 539, in get_experiment_by_name
    return self._tracking_client.get_experiment_by_name(name)
  File "/usr/local/lib/python3.8/dist-packages/mlflow/tracking/_tracking_service/client.py", line 236, in get_experiment_by_name
    return self.store.get_experiment_by_name(name)
  File "/usr/local/lib/python3.8/dist-packages/mlflow/store/tracking/rest_store.py", line 323, in get_experiment_by_name
    response_proto = self._call_endpoint(GetExperimentByName, req_body)
  File "/usr/local/lib/python3.8/dist-packages/mlflow/store/tracking/rest_store.py", line 60, in _call_endpoint
    return call_endpoint(self.get_host_creds(), endpoint, method, json_body, response_proto)
  File "/usr/local/lib/python3.8/dist-packages/mlflow/utils/rest_utils.py", line 216, in call_endpoint
    response = http_request(**call_kwargs)
  File "/usr/local/lib/python3.8/dist-packages/mlflow/utils/rest_utils.py", line 130, in http_request
    raise MlflowException(f"API request to {url} failed with exception {e}")
mlflow.exceptions.MlflowException: API request to http://host.docker.internal:5000/api/2.0/mlflow/experiments/get-by-name failed with exception Task received SIGTERM signal
[2024-03-11T16:59:40.037+0000] {taskinstance.py:1149} INFO - Marking task as FAILED. dag_id=Lead_scoring_training_pipeline, task_id=training_model, execution_date=20240311T165816, start_date=20240311T165829, end_date=20240311T165940
[2024-03-11T16:59:40.060+0000] {standard_task_runner.py:107} ERROR - Failed to execute job 91 for task training_model (API request to http://host.docker.internal:5000/api/2.0/mlflow/experiments/get-by-name failed with exception Task received SIGTERM signal; 1822)
[2024-03-11T16:59:40.113+0000] {process_utils.py:79} INFO - Process psutil.Process(pid=1822, status='terminated', exitcode=1, started='16:58:28') (1822) terminated with exit code 1
