[2024-03-11T16:13:29.285+0000] {taskinstance.py:1979} INFO - Dependencies all met for dep_context=non-requeueable deps ti=<TaskInstance: Lead_Scoring_Data_Engineering_Pipeline.mapping_city_tier manual__2024-03-11T16:13:18.228008+00:00 [queued]>
[2024-03-11T16:13:29.290+0000] {taskinstance.py:1979} INFO - Dependencies all met for dep_context=requeueable deps ti=<TaskInstance: Lead_Scoring_Data_Engineering_Pipeline.mapping_city_tier manual__2024-03-11T16:13:18.228008+00:00 [queued]>
[2024-03-11T16:13:29.290+0000] {taskinstance.py:2193} INFO - Starting attempt 1 of 2
[2024-03-11T16:13:29.347+0000] {taskinstance.py:2217} INFO - Executing <Task(PythonOperator): mapping_city_tier> on 2024-03-11 16:13:18.228008+00:00
[2024-03-11T16:13:29.353+0000] {standard_task_runner.py:60} INFO - Started process 735 to run task
[2024-03-11T16:13:29.358+0000] {standard_task_runner.py:87} INFO - Running: ['airflow', 'tasks', 'run', 'Lead_Scoring_Data_Engineering_Pipeline', 'mapping_city_tier', 'manual__2024-03-11T16:13:18.228008+00:00', '--job-id', '27', '--raw', '--subdir', 'DAGS_FOLDER/Lead_scoring_data_pipeline/lead_scoring_data_pipeline.py', '--cfg-path', '/tmp/tmp14q40w6s']
[2024-03-11T16:13:29.359+0000] {standard_task_runner.py:88} INFO - Job 27: Subtask mapping_city_tier
[2024-03-11T16:13:29.393+0000] {task_command.py:423} INFO - Running <TaskInstance: Lead_Scoring_Data_Engineering_Pipeline.mapping_city_tier manual__2024-03-11T16:13:18.228008+00:00 [running]> on host 19276f21f48e
[2024-03-11T16:13:29.451+0000] {taskinstance.py:2513} INFO - Exporting env vars: AIRFLOW_CTX_DAG_OWNER='airflow' AIRFLOW_CTX_DAG_ID='Lead_Scoring_Data_Engineering_Pipeline' AIRFLOW_CTX_TASK_ID='mapping_city_tier' AIRFLOW_CTX_EXECUTION_DATE='2024-03-11T16:13:18.228008+00:00' AIRFLOW_CTX_TRY_NUMBER='1' AIRFLOW_CTX_DAG_RUN_ID='manual__2024-03-11T16:13:18.228008+00:00'
[2024-03-11T16:13:29.453+0000] {logging_mixin.py:188} INFO - Exception thrown in map_city_tier : unable to open database file
[2024-03-11T16:13:29.453+0000] {taskinstance.py:2731} ERROR - Task failed with exception
Traceback (most recent call last):
  File "/usr/local/lib/python3.8/dist-packages/airflow/models/taskinstance.py", line 444, in _execute_task
    result = _execute_callable(context=context, **execute_callable_kwargs)
  File "/usr/local/lib/python3.8/dist-packages/airflow/models/taskinstance.py", line 414, in _execute_callable
    return execute_callable(context=context, **execute_callable_kwargs)
  File "/usr/local/lib/python3.8/dist-packages/airflow/operators/python.py", line 200, in execute
    return_value = self.execute_callable()
  File "/usr/local/lib/python3.8/dist-packages/airflow/operators/python.py", line 217, in execute_callable
    return self.python_callable(*self.op_args, **self.op_kwargs)
  File "/home/airflow/dags/Lead_scoring_data_pipeline/utils.py", line 187, in map_city_tier
    if conn:
UnboundLocalError: local variable 'conn' referenced before assignment
[2024-03-11T16:13:29.456+0000] {taskinstance.py:1149} INFO - Marking task as UP_FOR_RETRY. dag_id=Lead_Scoring_Data_Engineering_Pipeline, task_id=mapping_city_tier, execution_date=20240311T161318, start_date=20240311T161329, end_date=20240311T161329
[2024-03-11T16:13:29.473+0000] {standard_task_runner.py:107} ERROR - Failed to execute job 27 for task mapping_city_tier (local variable 'conn' referenced before assignment; 735)
[2024-03-11T16:13:29.488+0000] {local_task_job_runner.py:234} INFO - Task exited with return code 1
[2024-03-11T16:13:29.502+0000] {taskinstance.py:3312} INFO - 0 downstream tasks scheduled from follow-on schedule check
