[2024-03-11T17:04:31.297+0000] {taskinstance.py:1979} INFO - Dependencies all met for dep_context=non-requeueable deps ti=<TaskInstance: Lead_scoring_training_pipeline.training_model manual__2024-03-11T17:02:08.742205+00:00 [queued]>
[2024-03-11T17:04:31.302+0000] {taskinstance.py:1979} INFO - Dependencies all met for dep_context=requeueable deps ti=<TaskInstance: Lead_scoring_training_pipeline.training_model manual__2024-03-11T17:02:08.742205+00:00 [queued]>
[2024-03-11T17:04:31.302+0000] {taskinstance.py:2193} INFO - Starting attempt 2 of 2
[2024-03-11T17:04:31.328+0000] {taskinstance.py:2217} INFO - Executing <Task(PythonOperator): training_model> on 2024-03-11 17:02:08.742205+00:00
[2024-03-11T17:04:31.336+0000] {standard_task_runner.py:60} INFO - Started process 1956 to run task
[2024-03-11T17:04:31.340+0000] {standard_task_runner.py:87} INFO - Running: ['airflow', 'tasks', 'run', 'Lead_scoring_training_pipeline', 'training_model', 'manual__2024-03-11T17:02:08.742205+00:00', '--job-id', '98', '--raw', '--subdir', 'DAGS_FOLDER/Lead_scoring_training_pipeline/lead_scoring_training_pipeline.py', '--cfg-path', '/tmp/tmp4ekam6ed']
[2024-03-11T17:04:31.340+0000] {standard_task_runner.py:88} INFO - Job 98: Subtask training_model
[2024-03-11T17:04:31.377+0000] {task_command.py:423} INFO - Running <TaskInstance: Lead_scoring_training_pipeline.training_model manual__2024-03-11T17:02:08.742205+00:00 [running]> on host 026c09de2b63
[2024-03-11T17:04:31.424+0000] {taskinstance.py:2513} INFO - Exporting env vars: AIRFLOW_CTX_DAG_OWNER='airflow' AIRFLOW_CTX_DAG_ID='Lead_scoring_training_pipeline' AIRFLOW_CTX_TASK_ID='training_model' AIRFLOW_CTX_EXECUTION_DATE='2024-03-11T17:02:08.742205+00:00' AIRFLOW_CTX_TRY_NUMBER='2' AIRFLOW_CTX_DAG_RUN_ID='manual__2024-03-11T17:02:08.742205+00:00'
[2024-03-11T17:04:31.425+0000] {logging_mixin.py:188} INFO - /home/airflow/dags/Lead_scoring_data_pipeline
[2024-03-11T17:04:31.426+0000] {logging_mixin.py:188} INFO - ['data_validation_checks.py', 'constants.py', 'schema.py', 'lead_scoring_data_pipeline.py', 'utils.py', 'data', '.ipynb_checkpoints', 'mapping', '__pycache__', 'lead_scoring_data_cleaning.db']
[2024-03-11T17:04:31.426+0000] {logging_mixin.py:188} INFO - /home/mlfow/
[2024-03-11T17:04:31.426+0000] {logging_mixin.py:188} INFO - Lead_scoring_mlflow_production.db
[2024-03-11T17:04:31.426+0000] {logging_mixin.py:188} INFO - unable to open database file
[2024-03-11T17:04:31.429+0000] {logging_mixin.py:188} INFO - Loading 'features' table
[2024-03-11T17:04:35.586+0000] {logging_mixin.py:188} INFO - Loading 'target' table
[2024-03-11T17:04:35.844+0000] {utils.py:201} INFO - Creating mlflow experiment
[2024-03-11T17:04:36.202+0000] {connectionpool.py:810} WARNING - Retrying (JitteredRetry(total=4, connect=4, read=5, redirect=5, status=5)) after connection broken by 'NewConnectionError('<urllib3.connection.HTTPConnection object at 0x7fd5e0d7e6d0>: Failed to establish a new connection: [Errno 111] Connection refused')': /api/2.0/mlflow/experiments/create
[2024-03-11T17:04:40.207+0000] {connectionpool.py:810} WARNING - Retrying (JitteredRetry(total=3, connect=3, read=5, redirect=5, status=5)) after connection broken by 'NewConnectionError('<urllib3.connection.HTTPConnection object at 0x7fd5e0d7e760>: Failed to establish a new connection: [Errno 111] Connection refused')': /api/2.0/mlflow/experiments/create
[2024-03-11T17:04:46.511+0000] {local_task_job_runner.py:302} WARNING - State of this instance has been externally set to success. Terminating instance.
[2024-03-11T17:04:46.513+0000] {process_utils.py:131} INFO - Sending Signals.SIGTERM to group 1956. PIDs of all processes in the group: [1956]
[2024-03-11T17:04:46.513+0000] {process_utils.py:86} INFO - Sending the signal Signals.SIGTERM to group 1956
[2024-03-11T17:04:46.514+0000] {taskinstance.py:2483} ERROR - Received SIGTERM. Terminating subprocesses.
[2024-03-11T17:04:46.518+0000] {connectionpool.py:810} WARNING - Retrying (JitteredRetry(total=4, connect=4, read=5, redirect=5, status=5)) after connection broken by 'NewConnectionError('<urllib3.connection.HTTPConnection object at 0x7fd5e0d15820>: Failed to establish a new connection: [Errno 111] Connection refused')': /api/2.0/mlflow/experiments/get-by-name?experiment_name=Lead_scoring_mlflow_production
[2024-03-11T17:04:50.520+0000] {connectionpool.py:810} WARNING - Retrying (JitteredRetry(total=3, connect=3, read=5, redirect=5, status=5)) after connection broken by 'NewConnectionError('<urllib3.connection.HTTPConnection object at 0x7fd5e0d15970>: Failed to establish a new connection: [Errno 111] Connection refused')': /api/2.0/mlflow/experiments/get-by-name?experiment_name=Lead_scoring_mlflow_production
[2024-03-11T17:04:58.528+0000] {connectionpool.py:810} WARNING - Retrying (JitteredRetry(total=2, connect=2, read=5, redirect=5, status=5)) after connection broken by 'NewConnectionError('<urllib3.connection.HTTPConnection object at 0x7fd5e0c34f70>: Failed to establish a new connection: [Errno 111] Connection refused')': /api/2.0/mlflow/experiments/get-by-name?experiment_name=Lead_scoring_mlflow_production
[2024-03-11T17:05:14.546+0000] {connectionpool.py:810} WARNING - Retrying (JitteredRetry(total=1, connect=1, read=5, redirect=5, status=5)) after connection broken by 'NewConnectionError('<urllib3.connection.HTTPConnection object at 0x7fd5e0d7ed60>: Failed to establish a new connection: [Errno 111] Connection refused')': /api/2.0/mlflow/experiments/get-by-name?experiment_name=Lead_scoring_mlflow_production
[2024-03-11T17:05:46.534+0000] {process_utils.py:149} WARNING - process psutil.Process(pid=1956, name='airflow task runner: Lead_scoring_training_pipeline training_model manual__2024-03-11T17:02:08.742205+00:00 98', status='sleeping', started='17:04:31') did not respond to SIGTERM. Trying SIGKILL
[2024-03-11T17:05:46.537+0000] {process_utils.py:86} INFO - Sending the signal Signals.SIGKILL to group 1956
[2024-03-11T17:05:46.589+0000] {process_utils.py:79} INFO - Process psutil.Process(pid=1956, name='airflow task runner: Lead_scoring_training_pipeline training_model manual__2024-03-11T17:02:08.742205+00:00 98', status='terminated', exitcode=<Negsignal.SIGKILL: -9>, started='17:04:31') (1956) terminated with exit code Negsignal.SIGKILL
[2024-03-11T17:05:46.590+0000] {standard_task_runner.py:175} ERROR - Job 98 was killed before it finished (likely due to running out of memory)
